Workbook

Sheet Instruções
B3: Instruções
B5: Você é o novo analista financeiro da empresa e seu primeiro desafio é elaborar os demonstrativos financeiros de janeiro de 2026. Na aba “Dados” você tem a extração dos dados de uma plataforma de vendas. Sua missão é montar um DRE e um DFC diários para cada loja e produto e, com base nos resultados, apresentar a sua análise e insights sobre a situação de cada produto e loja. Pode seguir a DRE até o lucro operacional, não há necessidade de levar em consideração dívidas e impostos Pontos importantes: 1. A receita fica disponível em nossa conta 2 dias após a venda; 2. Comissões e reembolsos são descontados no ato da venda; 3. Essa plataforma cobra uma taxa de 5,00% sobre o valor da venda; 4. Os custos de produção e envio são pagos quando o produto é entregue ao cliente. Considere uma média de 7 dias a partir da data da comprar para a entrega ser efetuada.

Sheet Dados
B3: Base de Dados
B5: Data | C5: Loja | D5: Produto | E5: Status | F5: Valor Pago | G5: Data Reembolso | H5: Valor Reembolsado | I5: Custo de Produção | J5: Custo de Envio | K5: Comissão
B6: 46023 | C6: Loja B | D6: Produto W | E6: Pago | F6: 300 | I6: 30 | J6: 20 | K6: 150
B7: 46023 | C7: Loja C | D7: Produto Y | E7: Pago | F7: 400 | I7: 40 | J7: 10 | K7: 200
B8: 46024 | C8: Loja A | D8: Produto U | E8: Reembolsado | F8: 200 | G8: 46042 | H8: 200 | I8: 20 | J8: 19 | K8: 0
B9: 46024 | C9: Loja B | D9: Produto X | E9: Pago | F9: 350 | I9: 35 | J9: 18 | K9: 175
B10: 46024 | C10: Loja A | D10: Produto V | E10: Pago | F10: 250 | I10: 25 | J10: 12 | K10: 0
B11: 46024 | C11: Loja B | D11: Produto X | E11: Pago | F11: 350 | I11: 35 | J11: 19 | K11: 175
B12: 46025 | C12: Loja B | D12: Produto W | E12: Pago | F12: 300 | I12: 30 | J12: 17 | K12: 150
B13: 46025 | C13: Loja A | D13: Produto U | E13: Pago | F13: 200 | I13: 20 | J13: 13 | K13: 100
B14: 46025 | C14: Loja C | D14: Produto Z | E14: Pago | F14: 600 | I14: 60 | J14: 19 | K14: 300
B15: 46025 | C15: Loja A | D15: Produto U | E15: Reembolsado | F15: 200 | G15: 46037 | H15: 150 | I15: 20 | J15: 14 | K15: 0
B16: 46025 | C16: Loja A | D16: Produto V | E16: Pago | F16: 250 | I16: 25 | J16: 18 | K16: 0
B17: 46025 | C17: Loja C | D17: Produto Z | E17: Pago | F17: 600 | I17: 60 | J17: 14 | K17: 300
B18: 46025 | C18: Loja B | D18: Produto W | E18: Pago | F18: 300 | I18: 30 | J18: 17 | K18: 150
B19: 46026 | C19: Loja C | D19: Produto Y | E19: Pago | F19: 400 | I19: 40 | J19: 16 | K19: 200
B20: 46026 | C20: Loja A | D20: Produto U | E20: Pago | F20: 200 | I20: 20 | J20: 18 | K20: 0
B21: 46026 | C21: Loja A | D21: Produto V | E21: Pago | F21: 250 | I21: 25 | J21: 10 | K21: 125
B22: 46026 | C22: Loja B | D22: Produto X | E22: Pago | F22: 350 | I22: 35 | J22: 12 | K22: 175
B23: 46026 | C23: Loja C | D23: Produto Y | E23: Pago | F23: 400 | I23: 40 | J23: 10 | K23: 0
B24: 46026 | C24: Loja C | D24: Produto Z | E24: Pago | F24: 600 | I24: 60 | J24: 14 | K24: 300
B25: 46026 | C25: Loja C | D25: Produto Y | E25: Pago | F25: 400 | I25: 40 | J25: 16 | K25: 200
B26: 46027 | C26: Loja C | D26: Produto Y | E26: Reembolsado | F26: 400 | G26: 46027 | H26: 280 | I26: 40 | J26: 15 | K26: 200
B27: 46027 | C27: Loja B | D27: Produto X | E27: Reembolsado | F27: 350 | G27: 46047 | H27: 300 | I27: 35 | J27: 17 | K27: 175
B28: 46027 | C28: Loja A | D28: Produto V | E28: Reembolsado | F28: 250 | G28: 46028 | H28: 250 | I28: 25 | J28: 14 | K28: 0
B29: 46027 | C29: Loja B | D29: Produto X | E29: Pago | F29: 350 | I29: 35 | J29: 11 | K29: 175
B30: 46028 | C30: Loja A | D30: Produto V | E30: Pago | F30: 250 | I30: 25 | J30: 10 | K30: 0
B31: 46028 | C31: Loja B | D31: Produto W | E31: Pago | F31: 300 | I31: 30 | J31: 20 | K31: 150
B32: 46028 | C32: Loja C | D32: Produto Y | E32: Pago | F32: 400 | I32: 40 | J32: 13 | K32: 200
B33: 46028 | C33: Loja B | D33: Produto W | E33: Pago | F33: 300 | I33: 30 | J33: 12 | K33: 150
B34: 46028 | C34: Loja B | D34: Produto X | E34: Pago | F34: 350 | I34: 35 | J34: 12 | K34: 175
B35: 46028 | C35: Loja A | D35: Produto V | E35: Pago | F35: 250 | I35: 25 | J35: 12 | K35: 0
B36: 46028 | C36: Loja C | D36: Produto Z | E36: Pago | F36: 600 | I36: 60 | J36: 13 | K36: 300
B37: 46028 | C37: Loja B | D37: Produto X | E37: Pago | F37: 350 | I37: 35 | J37: 14 | K37: 175
B38: 46029 | C38: Loja A | D38: Produto U | E38: Pago | F38: 200 | I38: 20 | J38: 14 | K38: 100
B39: 46029 | C39: Loja A | D39: Produto V | E39: Pago | F39: 250 | I39: 25 | J39: 20 | K39: 0
B40: 46031 | C40: Loja C | D40: Produto Y | E40: Pago | F40: 400 | I40: 40 | J40: 14 | K40: 200
... B53: 46034 | C53: Loja B | D53: Produto X | E53: Pago | F53: 350 | I53: 35 | J53: 17 | K53: 0
B54: 46034 | C54: Loja A | D54: Produto V | E54: Reembolsado | F54: 250 | G54: 46039 | H54: 200 | I54: 25 | J54: 18 | K54: 125
B55: 46035 | C55: Loja B | D55: Produto W | E55: Reembolsado | F55: 300 | G55: 46035 | H55: 150 | I55: 30 | J55: 15 | K55: 150
...

Sheet DFs (2)
B3: Demonstrações Financeiras
B6: DRE
B7: Receita Bruta | C7: =SUM(Dados!F6:F155) -> 51400
B8: (-) Deduções/Taxas | C8: =-C7*5% -> -2570
B9: (=) Receita Líquida | C9: =SUM(C7:C8) -> 48830
B10: (-) CPV (Custo de Vendas)
B11: Custo de Produção | C11: =-SUM(Dados!$I$6:$I$155) -> -5140
B12: Custo de Envio | C12: =-SUM(Dados!$J$6:$J$155) -> -2257
B13: (-) Despesas Variáveis
B14: Comissões | C14: =-SUM(Dados!K6:K155) -> -20475
B15: Reembolsos | C15: =-SUM(Dados!$H$6:$H$155) -> -6345
B16: (=) Lucro Operacional | C16: =SUM(C9:C15) -> 14613
B19: DFC COMPLETO | I19: DFC DIARIO | L19: DFC DIARIO POR PRODUTO
B20: Data | C20: Saldo Inicial | D20: Entradas | E20: Saidas | F20: Saldo Final | I20: Data do Caixa | J20: 46027 | L20: Data do Caixa | M20: =$J$20 -> 46027
B21: 46023 | C21: 0 | D21: =SUMIF(Dados!$B$6:$B$155,'DFs (2)'!$B21-2,Dados!$F$6:$F$155) -> 0 | E21: =-(5%*SUMIF(Dados!$B$6:$B$155,'DFs (2)'!$B21,Dados!$F$6:$F$155)+SUMIF(Dados!$B$6:$B$155,'DFs (2)'!$B21,Dados!$K$6:$K$155)+SUMIF(Dados!$G$6:$G$155,'DFs (2)'!$B21,Dados!$H$6:$H$155)+SUMIF(Dados!$B$6:$B$155,'DFs (2)'!$B21-7,Dados!$I$6:$I$155)+SUMIF(Dados!$B$6:$B$155,'DFs (2)'!$B21-7,Dados!$J$6:$J$155)) -> -385 | F21: =SUM(C21:E21) -> -385 | I21: Saldo Inicial de Caixa | J21: =SUMIF(Dados!$B$6:$B$155,"<="&($J$20-3),Dados!$F$6:$F$155)-0.05*SUMIF(Dados!$B$6:$B$155,"<="&($J$20-1),Dados!$F$6:$F$155)-SUMIF(Dados!$B$6:$B$155,"<="&($J$20-1),Dados!$K$6:$K$155)-SUMIF(Dados!$G$6:$G$155,"<="&($J$20-1),Dados!$H$6:$H$155)-SUMIF(Dados!$B$6:$B$155,"<="&($J$20-8),Dados!$I$6:$I$155)-SUMIF(Dados!$B$6:$B$155,"<="&($J$20-8),Dados!$J$6:$J$155) -> -1195 | L21: Produto | M21: Produto U
B22: 46024 | C22: =F21 -> -385 | D22: =SUMIF(Dados!$B$6:$B$155,'DFs (2)'!$B22-2,Dados!$F$6:$F$155) -> 0 | E22: =-(5%*SUMIF(Dados!$B$6:$B$155,'DFs (2)'!$B22,Dados!$F$6:$F$155)+SUMIF(Dados!$B$6:$B$155,'DFs (2)'!$B22,Dados!$K$6:$K$155)+SUMIF(Dados!$G$6:$G$155,'DFs (2)'!$B22,Dados!$H$6:$H$155)+SUMIF(Dados!$B$6:$B$155,'DFs (2)'!$B22-7,Dados!$I$6:$I$155)+SUMIF(Dados!$B$6:$B$155,'DFs (2)'!$B22-7,Dados!$J$6:$J$155)) -> -407.5 | F22: =SUM(C22:E22) -> -792.5 | I22: Entradas | L22: Saldo Inicial de Caixa | M22: =SUMIFS(Dados!$F$6:$F$155, Dados!$B$6:$B$155, "<="&('DFs (2)'!$J$20-3), Dados!$D$6:$D$155, 'DFs (2)'!$M$21)-0.05*SUMIFS(Dados!$F$6:$F$155, Dados!$B$6:$B$155, "<="&('DFs (2)'!$J$20-1), Dados!$D$6:$D$155, 'DFs (2)'!$M$21)-SUMIFS(Dados!$K$6:$K$155, Dados!$B$6:$B$155, "<="&('DFs (2)'!$J$20-1), Dados!$D$6:$D$155, 'DFs (2)'!$M$21)-SUMIFS(Dados!$H$6:$H$155, Dados!$G$6:$G$155, "<="&('DFs (2)'!$J$20-1), Dados!$D$6:$D$155, 'DFs (2)'!$M$21)-SUMIFS(Dados!$I$6:$I$155, Dados!$B$6:$B$155, "<="&('DFs (2)'!$J$20-8), Dados!$D$6:$D$155, 'DFs (2)'!$M$21)-SUMIFS(Dados!$J$6:$J$155, Dados!$B$6:$B$155, "<="&('DFs (2)'!$J$20-8), Dados!$D$6:$D$155, 'DFs (2)'!$M$21) -> 60
B23: 46025 | C23: =F22 -> -792.5 | D23: =SUMIF(Dados!$B$6:$B$155,'DFs (2)'!$B23-2,Dados!$F$6:$F$155) -> 700 | E23: =-(5%*SUMIF(Dados!$B$6:$B$155,'DFs (2)'!$B23,Dados!$F$6:$F$155)+SUMIF(Dados!$B$6:$B$155,'DFs (2)'!$B23,Dados!$K$6:$K$155)+SUMIF(Dados!$G$6:$G$155,'DFs (2)'!$B23,Dados!$H$6:$H$155)+SUMIF(Dados!$B$6:$B$155,'DFs (2)'!$B23-7,Dados!$I$6:$I$155)+SUMIF(Dados!$B$6:$B$155,'DFs (2)'!$B23-7,Dados!$J$6:$J$155)) -> -1122.5 | F23: =SUM(C23:E23) -> -1215 | I23: Total de Vendas | J23: =SUMIF(Dados!$B$6:$B$155,'DFs (2)'!$J$20-2,Dados!$F$6:$F$155) -> 2450 | L23: Entradas
B24: 46026 | C24: =F23 -> -1215 | D24: =SUMIF(Dados!$B$6:$B$155,'DFs (2)'!$B24-2,Dados!$F$6:$F$155) -> 1150 | E24: =-(5%*SUMIF(Dados!$B$6:$B$155,'DFs (2)'!$B24,Dados!$F$6:$F$155)+SUMIF(Dados!$B$6:$B$155,'DFs (2)'!$B24,Dados!$K$6:$K$155)+SUMIF(Dados!$G$6:$G$155,'DFs (2)'!$B24,Dados!$H$6:$H$155)+SUMIF(Dados!$B$6:$B$155,'DFs (2)'!$B24-7,Dados!$I$6:$I$155)+SUMIF(Dados!$B$6:$B$155,'DFs (2)'!$B24-7,Dados!$J$6:$J$155)) -> -1130 | F24: =SUM(C24:E24) -> -1195 | I24: Saídas | L24: Total de Vendas | M24: =SUMIFS(Dados!$F$6:$F$155,Dados!$B$6:$B$155, 'DFs (2)'!$J$20-2,Dados!$D$6:$D$155, 'DFs (2)'!$M$21) -> 400
B25: 46027 | C25: =F24 -> -1195 | D25: =SUMIF(Dados!$B$6:$B$155,'DFs (2)'!$B25-2,Dados!$F$6:$F$155) -> 2450 | E25: =-(5%*SUMIF(Dados!$B$6:$B$155,'DFs (2)'!$B25,Dados!$F$6:$F$155)+SUMIF(Dados!$B$6:$B$155,'DFs (2)'!$B25,Dados!$K$6:$K$155)+SUMIF(Dados!$G$6:$G$155,'DFs (2)'!$B25,Dados!$H$6:$H$155)+SUMIF(Dados!$B$6:$B$155,'DFs (2)'!$B25-7,Dados!$I$6:$I$155)+SUMIF(Dados!$B$6:$B$155,'DFs (2)'!$B25-7,Dados!$J$6:$J$155)) -> -897.5 | F25: =SUM(C25:E25) -> 357.5 | I25: Taxas | J25: =-(5%*SUMIF(Dados!$B$6:$B$155,'DFs (2)'!$J$20,Dados!$F$6:$F$155)) -> -67.5 | L25: Saídas
B26: 46028 | C26: =F25 -> 357.5 | D26: =SUMIF(Dados!$B$6:$B$155,'DFs (2)'!$B26-2,Dados!$F$6:$F$155) -> 2600 | E26: =-(5%*SUMIF(Dados!$B$6:$B$155,'DFs (2)'!$B26,Dados!$F$6:$F$155)+SUMIF(Dados!$B$6:$B$155,'DFs (2)'!$B26,Dados!$K$6:$K$155)+SUMIF(Dados!$G$6:$G$155,'DFs (2)'!$B26,Dados!$H$6:$H$155)+SUMIF(Dados!$B$6:$B$155,'DFs (2)'!$B26-7,Dados!$I$6:$I$155)+SUMIF(Dados!$B$6:$B$155,'DFs (2)'!$B26-7,Dados!$J$6:$J$155)) -> -1540 | F26: =SUM(C26:E26) -> 1417.5 | I26: Comissão | J26: =-SUMIF(Dados!$B$6:$B$155,'DFs (2)'!$J$20,Dados!$K$6:$K$155) -> -550 | L26: Taxas | M26: =-(5%*SUMIFS(Dados!$F$6:$F$155,Dados!$B$6:$B$155, 'DFs (2)'!$J$20,Dados!$D$6:$D$155, 'DFs (2)'!$M$21)) -> 0
B27: 46029 | C27: =F26 -> 1417.5 | D27: =SUMIF(Dados!$B$6:$B$155,'DFs (2)'!$B27-2,Dados!$F$6:$F$155) -> 1350 | E27: =-(5%*SUMIF(Dados!$B$6:$B$155,'DFs (2)'!$B27,Dados!$F$6:$F$155)+SUMIF(Dados!$B$6:$B$155,'DFs (2)'!$B27,Dados!$K$6:$K$155)+SUMIF(Dados!$G$6:$G$155,'DFs (2)'!$B27,Dados!$H$6:$H$155)+SUMIF(Dados!$B$6:$B$155,'DFs (2)'!$B27-7,Dados!$I$6:$I$155)+SUMIF(Dados!$B$6:$B$155,'DFs (2)'!$B27-7,Dados!$J$6:$J$155)) -> -122.5 | F27: =SUM(C27:E27) -> 2645 | I27: Reembolso | J27: =-SUMIF(Dados!$G$6:$G$155,'DFs (2)'!$J$20,Dados!$H$6:$H$155) -> -280 | L27: Comissão | M27: =-SUMIFS(Dados!$K$6:$K$155,Dados!$B$6:$B$155, 'DFs (2)'!$J$20, Dados!$D$6:$D$155, 'DFs (2)'!$M$21) -> 0
B28: 46030 | C28: =F27 -> 2645 | D28: =SUMIF(Dados!$B$6:$B$155,'DFs (2)'!$B28-2,Dados!$F$6:$F$155) -> 2800 | E28: =-(5%*SUMIF(Dados!$B$6:$B$155,'DFs (2)'!$B28,Dados!$F$6:$F$155)+SUMIF(Dados!$B$6:$B$155,'DFs (2)'!$B28,Dados!$K$6:$K$155)+SUMIF(Dados!$G$6:$G$155,'DFs (2)'!$B28,Dados!$H$6:$H$155)+SUMIF(Dados!$B$6:$B$155,'DFs (2)'!$B28-7,Dados!$I$6:$I$155)+SUMIF(Dados!$B$6:$B$155,'DFs (2)'!$B28-7,Dados!$J$6:$J$155)) -> -100 | F28: =SUM(C28:E28) -> 5345 | I28: Custo de produção | J28: =-SUMIF(Dados!$B$6:$B$155,'DFs (2)'!$J$20-7,Dados!$I$6:$I$155) -> 0 | L28: Reembolso | M28: =-SUMIFS(Dados!$H$6:$H$155,Dados!$G$6:$G$155, 'DFs (2)'!$J$20,Dados!$D$6:$D$155, 'DFs (2)'!$M$21) -> 0
B29: 46031 | C29: =F28 -> 5345 | D29: =SUMIF(Dados!$B$6:$B$155,'DFs (2)'!$B29-2,Dados!$F$6:$F$155) -> 450 | E29: =-(5%*SUMIF(Dados!$B$6:$B$155,'DFs (2)'!$B29,Dados!$F$6:$F$155)+SUMIF(Dados!$B$6:$B$155,'DFs (2)'!$B29,Dados!$K$6:$K$155)+SUMIF(Dados!$G$6:$G$155,'DFs (2)'!$B29,Dados!$H$6:$H$155)+SUMIF(Dados!$B$6:$B$155,'DFs (2)'!$B29-7,Dados!$I$6:$I$155)+SUMIF(Dados!$B$6:$B$155,'DFs (2)'!$B29-7,Dados!$J$6:$J$155)) -> -733 | F29: =SUM(C29:E29) -> 5062 | I29: Custo de Envio | J29: =-SUMIF(Dados!$B$6:$B$155,'DFs (2)'!$J$20-7,Dados!$J$6:$J$155) -> 0 | L29: Custo de produção | M29: =-SUMIFS(Dados!$I$6:$I$155,Dados!$B$6:$B$155, 'DFs (2)'!$J$20-7,Dados!$D$6:$D$155, 'DFs (2)'!$M$21) -> 0
B30: 46032 | C30: =F29 -> 5062 | D30: =SUMIF(Dados!$B$6:$B$155,'DFs (2)'!$B30-2,Dados!$F$6:$F$155) -> 0 | E30: =-(5%*SUMIF(Dados!$B$6:$B$155,'DFs (2)'!$B30,Dados!$F$6:$F$155)+SUMIF(Dados!$B$6:$B$155,'DFs (2)'!$B30,Dados!$K$6:$K$155)+SUMIF(Dados!$G$6:$G$155,'DFs (2)'!$B30,Dados!$H$6:$H$155)+SUMIF(Dados!$B$6:$B$155,'DFs (2)'!$B30-7,Dados!$I$6:$I$155)+SUMIF(Dados!$B$6:$B$155,'DFs (2)'!$B30-7,Dados!$J$6:$J$155)) -> -742 | F30: =SUM(C30:E30) -> 4320 | I30: Saldo Final de Caixa | J30: =SUM(J21:J29) -> 357.5 | L30: Custo de Envio | M30: =-SUMIFS(Dados!$J$6:$J$155,Dados!$B$6:$B$155, 'DFs (2)'!$J$20-7,Dados!$D$6:$D$155, 'DFs (2)'!$M$21) -> 0
B31: 46033 | C31: =F30 -> 4320 | D31: =SUMIF(Dados!$B$6:$B$155,'DFs (2)'!$B31-2,Dados!$F$6:$F$155) -> 1000 | E31: =-(5%*SUMIF(Dados!$B$6:$B$155,'DFs (2)'!$B31,Dados!$F$6:$F$155)+SUMIF(Dados!$B$6:$B$155,'DFs (2)'!$B31,Dados!$K$6:$K$155)+SUMIF(Dados!$G$6:$G$155,'DFs (2)'!$B31,Dados!$H$6:$H$155)+SUMIF(Dados!$B$6:$B$155,'DFs (2)'!$B31-7,Dados!$I$6:$I$155)+SUMIF(Dados!$B$6:$B$155,'DFs (2)'!$B31-7,Dados!$J$6:$J$155)) -> -796 | F31: =SUM(C31:E31) -> 4524 | L31: Saldo Final de Caixa | M31: =SUM(M22:M30) -> 460
B32: 46034 | C32: =F31 -> 4524 | D32: =SUMIF(Dados!$B$6:$B$155,'DFs (2)'!$B32-2,Dados!$F$6:$F$155) -> 1200 | E32: =-(5%*SUMIF(Dados!$B$6:$B$155,'DFs (2)'!$B32,Dados!$F$6:$F$155)+SUMIF(Dados!$B$6:$B$155,'DFs (2)'!$B32,Dados!$K$6:$K$155)+SUMIF(Dados!$G$6:$G$155,'DFs (2)'!$B32,Dados!$H$6:$H$155)+SUMIF(Dados!$B$6:$B$155,'DFs (2)'!$B32-7,Dados!$I$6:$I$155)+SUMIF(Dados!$B$6:$B$155,'DFs (2)'!$B32-7,Dados!$J$6:$J$155)) -> -1254.5 | F32: =SUM(C32:E32) -> 4469.5
B33: 46035 | C33: =F32 -> 4469.5 | D33: =SUMIF(Dados!$B$6:$B$155,'DFs (2)'!$B33-2,Dados!$F$6:$F$155) -> 800 | E33: =-(5%*SUMIF(Dados!$B$6:$B$155,'DFs (2)'!$B33,Dados!$F$6:$F$155)+SUMIF(Dados!$B$6:$B$155,'DFs (2)'!$B33,Dados!$K$6:$K$155)+SUMIF(Dados!$G$6:$G$155,'DFs (2)'!$B33,Dados!$H$6:$H$155)+SUMIF(Dados!$B$6:$B$155,'DFs (2)'!$B33-7,Dados!$I$6:$I$155)+SUMIF(Dados!$B$6:$B$155,'DFs (2)'!$B33-7,Dados!$J$6:$J$155)) -> -2193.5 | F33: =SUM(C33:E33) -> 3076 | I33: DFC DIARIO POR LOJA
B34: 46036 | C34: =F33 -> 3076 | D34: =SUMIF(Dados!$B$6:$B$155,'DFs (2)'!$B34-2,Dados!$F$6:$F$155) -> 2250 | E34: =-(5%*SUMIF(Dados!$B$6:$B$155,'DFs (2)'!$B34,Dados!$F$6:$F$155)+SUMIF(Dados!$B$6:$B$155,'DFs (2)'!$B34,Dados!$K$6:$K$155)+SUMIF(Dados!$G$6:$G$155,'DFs (2)'!$B34,Dados!$H$6:$H$155)+SUMIF(Dados!$B$6:$B$155,'DFs (2)'!$B34-7,Dados!$I$6:$I$155)+SUMIF(Dados!$B$6:$B$155,'DFs (2)'!$B34-7,Dados!$J$6:$J$155)) -> -1194 | F34: =SUM(C34:E34) -> 4132 | I34: Data do Caixa | J34: =$J$20 -> 46027
B35: 46037 | C35: =F34 -> 4132 | D35: =SUMIF(Dados!$B$6:$B$155,'DFs (2)'!$B35-2,Dados!$F$6:$F$155) -> 3350 | E35: =-(5%*SUMIF(Dados!$B$6:$B$155,'DFs (2)'!$B35,Dados!$F$6:$F$155)+SUMIF(Dados!$B$6:$B$155,'DFs (2)'!$B35,Dados!$K$6:$K$155)+SUMIF(Dados!$G$6:$G$155,'DFs (2)'!$B35,Dados!$H$6:$H$155)+SUMIF(Dados!$B$6:$B$155,'DFs (2)'!$B35-7,Dados!$I$6:$I$155)+SUMIF(Dados!$B$6:$B$155,'DFs (2)'!$B35-7,Dados!$J$6:$J$155)) -> -1367.5 | F35: =SUM(C35:E35) -> 6114.5 | I35: Loja | J35: Loja B
B36: 46038 | C36: =F35 -> 6114.5 | D36: =SUMIF(Dados!$B$6:$B$155,'DFs (2)'!$B36-2,Dados!$F$6:$F$155) -> 2300 | E36: =-(5%*SUMIF(Dados!$B$6:$B$155,'DFs (2)'!$B36,Dados!$F$6:$F$155)+SUMIF(Dados!$B$6:$B$155,'DFs (2)'!$B36,Dados!$K$6:$K$155)+SUMIF(Dados!$G$6:$G$155,'DFs (2)'!$B36,Dados!$H$6:$H$155)+SUMIF(Dados!$B$6:$B$155,'DFs (2)'!$B36-7,Dados!$I$6:$I$155)+SUMIF(Dados!$B$6:$B$155,'DFs (2)'!$B36-7,Dados!$J$6:$J$155)) -> -1114 | F36: =SUM(C36:E36) -> 7300.5 | I36: Saldo Inicial de Caixa | J36: =SUMIFS(Dados!$F$6:$F$155,Dados!$B$6:$B$155,"<="&($J$20-3),Dados!$C$6:$C$155,$J$35)-0.05*SUMIFS(Dados!$F$6:$F$155,Dados!$B$6:$B$155,"<="&($J$20-1),Dados!$C$6:$C$155,$J$35)-SUMIFS(Dados!$K$6:$K$155,Dados!$B$6:$B$155,"<="&($J$20-1),Dados!$C$6:$C$155,$J$35)-SUMIFS(Dados!$H$6:$H$155,Dados!$G$6:$G$155,"<="&($J$20-1),Dados!$C$6:$C$155,$J$35)-SUMIFS(Dados!$I$6:$I$155,Dados!$B$6:$B$155,"<="&($J$20-8),Dados!$C$6:$C$155,$J$35)-SUMIFS(Dados!$J$6:$J$155,Dados!$B$6:$B$155,"<="&($J$20-8),Dados!$C$6:$C$155,$J$35) -> -72.5
B37: 46039 | C37: =F36 -> 7300.5 | D37: =SUMIF(Dados!$B$6:$B$155,'DFs (2)'!$B37-2,Dados!$F$6:$F$155) -> 1850 | E37: =-(5%*SUMIF(Dados!$B$6:$B$155,'DFs (2)'!$B37,Dados!$F$6:$F$155)+SUMIF(Dados!$B$6:$B$155,'DFs (2)'!$B37,Dados!$K$6:$K$155)+SUMIF(Dados!$G$6:$G$155,'DFs (2)'!$B37,Dados!$H$6:$H$155)+SUMIF(Dados!$B$6:$B$155,'DFs (2)'!$B37-7,Dados!$I$6:$I$155)+SUMIF(Dados!$B$6:$B$155,'DFs (2)'!$B37-7,Dados!$J$6:$J$155)) -> -1353.5 | F37: =SUM(C37:E37) -> 7797 | I37: Entradas
B38: 46040 | C38: =F37 -> 7797 | D38: =SUMIF(Dados!$B$6:$B$155,'DFs (2)'!$B38-2,Dados!$F$6:$F$155) -> 2000 | E38: =-(5%*SUMIF(Dados!$B$6:$B$155,'DFs (2)'!$B38,Dados!$F$6:$F$155)+SUMIF(Dados!$B$6:$B$155,'DFs (2)'!$B38,Dados!$K$6:$K$155)+SUMIF(Dados!$G$6:$G$155,'DFs (2)'!$B38,Dados!$H$6:$H$155)+SUMIF(Dados!$B$6:$B$155,'DFs (2)'!$B38-7,Dados!$I$6:$I$155)+SUMIF(Dados!$B$6:$B$155,'DFs (2)'!$B38-7,Dados!$J$6:$J$155)) -> -827 | F38: =SUM(C38:E38) -> 8970 | I38: Total de Vendas | J38: =SUMIFS(Dados!$F$6:$F$155,Dados!$B$6:$B$155,'DFs (2)'!$J$20-2,Dados!$C$6:$C$155,'DFs (2)'!$J$35) -> 600
B39: 46041 | C39: =F38 -> 8970 | D39: =SUMIF(Dados!$B$6:$B$155,'DFs (2)'!$B39-2,Dados!$F$6:$F$155) -> 2050 | E39: =-(5%*SUMIF(Dados!$B$6:$B$155,'DFs (2)'!$B39,Dados!$F$6:$F$155)+SUMIF(Dados!$B$6:$B$155,'DFs (2)'!$B39,Dados!$K$6:$K$155)+SUMIF(Dados!$G$6:$G$155,'DFs (2)'!$B39,Dados!$H$6:$H$155)+SUMIF(Dados!$B$6:$B$155,'DFs (2)'!$B39-7,Dados!$I$6:$I$155)+SUMIF(Dados!$B$6:$B$155,'DFs (2)'!$B39-7,Dados!$J$6:$J$155)) -> -1480 | F39: =SUM(C39:E39) -> 9540 | I39: Saídas
B40: 46042 | C40: =F39 -> 9540 | D40: =SUMIF(Dados!$B$6:$B$155,'DFs (2)'!$B40-2,Dados!$F$6:$F$155) -> 800 | E40: =-(5%*SUMIF(Dados!$B$6:$B$155,'DFs (2)'!$B40,Dados!$F$6:$F$155)+SUMIF(Dados!$B$6:$B$155,'DFs (2)'!$B40,Dados!$K$6:$K$155)+SUMIF(Dados!$G$6:$G$155,'DFs (2)'!$B40,Dados!$H$6:$H$155)+SUMIF(Dados!$B$6:$B$155,'DFs (2)'!$B40-7,Dados!$I$6:$I$155)+SUMIF(Dados!$B$6:$B$155,'DFs (2)'!$B40-7,Dados!$J$6:$J$155)) -> -2098.5 | F40: =SUM(C40:E40) -> 8241.5 | I40: Taxas | J40: =-(5%*SUMIFS(Dados!$F$6:$F$155,Dados!$B$6:$B$155, 'DFs (2)'!$J$20,Dados!$C$6:$C$155, 'DFs (2)'!$J$35)) -> -35
B41: 46043 | C41: =F40 -> 8241.5 | D41: =SUMIF(Dados!$B$6:$B$155,'DFs (2)'!$B41-2,Dados!$F$6:$F$155) -> 1900 | E41: =-(5%*SUMIF(Dados!$B$6:$B$155,'DFs (2)'!$B41,Dados!$F$6:$F$155)+SUMIF(Dados!$B$6:$B$155,'DFs (2)'!$B41,Dados!$K$6:$K$155)+SUMIF(Dados!$G$6:$G$155,'DFs (2)'!$B41,Dados!$H$6:$H$155)+SUMIF(Dados!$B$6:$B$155,'DFs (2)'!$B41-7,Dados!$I$6:$I$155)+SUMIF(Dados!$B$6:$B$155,'DFs (2)'!$B41-7,Dados!$J$6:$J$155)) -> -1037.5 | F41: =SUM(C41:E41) -> 9104 | I41: Comissão | J41: =-SUMIFS(Dados!$K$6:$K$155,Dados!$B$6:$B$155, 'DFs (2)'!$J$20,Dados!$C$6:$C$155, 'DFs (2)'!$J$35) -> -350
B42: 46044 | C42: =F41 -> 9104 | D42: =SUMIF(Dados!$B$6:$B$155,'DFs (2)'!$B42-2,Dados!$F$6:$F$155) -> 2450 | E42: =-(5%*SUMIF(Dados!$B$6:$B$155,'DFs (2)'!$B42,Dados!$F$6:$F$155)+SUMIF(Dados!$B$6:$B$155,'DFs (2)'!$B42,Dados!$K$6:$K$155)+SUMIF(Dados!$G$6:$G$155,'DFs (2)'!$B42,Dados!$H$6:$H$155)+SUMIF(Dados!$B$6:$B$155,'DFs (2)'!$B42-7,Dados!$I$6:$I$155)+SUMIF(Dados!$B$6:$B$155,'DFs (2)'!$B42-7,Dados!$J$6:$J$155)) -> -690.5 | F42: =SUM(C42:E42) -> 10863.5 | I42: Reembolso | J42: =-SUMIFS(Dados!$H$6:$H$155,Dados!$G$6:$G$155, 'DFs (2)'!$J$20,Dados!$C$6:$C$155, 'DFs (2)'!$J$35) -> 0
B43: 46045 | C43: =F42 -> 10863.5 | D43: =SUMIF(Dados!$B$6:$B$155,'DFs (2)'!$B43-2,Dados!$F$6:$F$155) -> 1650 | E43: =-(5%*SUMIF(Dados!$B$6:$B$155,'DFs (2)'!$B43,Dados!$F$6:$F$155)+SUMIF(Dados!$B$6:$B$155,'DFs (2)'!$B43,Dados!$K$6:$K$155)+SUMIF(Dados!$G$6:$G$155,'DFs (2)'!$B43,Dados!$H$6:$H$155)+SUMIF(Dados!$B$6:$B$155,'DFs (2)'!$B43-7,Dados!$I$6:$I$155)+SUMIF(Dados!$B$6:$B$155,'DFs (2)'!$B43-7,Dados!$J$6:$J$155)) -> -1911.5 | F43: =SUM(C43:E43) -> 10602 | I43: Custo de produção | J43: =-SUMIFS(Dados!$I$6:$I$155,Dados!$B$6:$B$155, 'DFs (2)'!$J$20-7,Dados!$C$6:$C$155, 'DFs (2)'!$J$35) -> 0
B44: 46046 | C44: =F43 -> 10602 | D44: =SUMIF(Dados!$B$6:$B$155,'DFs (2)'!$B44-2,Dados!$F$6:$F$155) -> 1050 | E44: =-(5%*SUMIF(Dados!$B$6:$B$155,'DFs (2)'!$B44,Dados!$F$6:$F$155)+SUMIF(Dados!$B$6:$B$155,'DFs (2)'!$B44,Dados!$K$6:$K$155)+SUMIF(Dados!$G$6:$G$155,'DFs (2)'!$B44,Dados!$H$6:$H$155)+SUMIF(Dados!$B$6:$B$155,'DFs (2)'!$B44-7,Dados!$I$6:$I$155)+SUMIF(Dados!$B$6:$B$155,'DFs (2)'!$B44-7,Dados!$J$6:$J$155)) -> -861 | F44: =SUM(C44:E44) -> 10791 | I44: Custo de Envio | J44: =-SUMIFS(Dados!$J$6:$J$155,Dados!$B$6:$B$155, 'DFs (2)'!$J$20-7,Dados!$C$6:$C$155, 'DFs (2)'!$J$35) -> 0
B45: 46047 | C45: =F44 -> 10791 | D45: =SUMIF(Dados!$B$6:$B$155,'DFs (2)'!$B45-2,Dados!$F$6:$F$155) -> 2250 | E45: =-(5%*SUMIF(Dados!$B$6:$B$155,'DFs (2)'!$B45,Dados!$F$6:$F$155)+SUMIF(Dados!$B$6:$B$155,'DFs (2)'!$B45,Dados!$K$6:$K$155)+SUMIF(Dados!$G$6:$G$155,'DFs (2)'!$B45,Dados!$H$6:$H$155)+SUMIF(Dados!$B$6:$B$155,'DFs (2)'!$B45-7,Dados!$I$6:$I$155)+SUMIF(Dados!$B$6:$B$155,'DFs (2)'!$B45-7,Dados!$J$6:$J$155)) -> -1829 | F45: =SUM(C45:E45) -> 11212 | I45: Saldo Final de Caixa | J45: =SUM(J36:J44) -> 142.5
B46: 46048 | C46: =F45 -> 11212 | D46: =SUMIF(Dados!$B$6:$B$155,'DFs (2)'!$B46-2,Dados!$F$6:$F$155) -> 1300 | E46: =-(5%*SUMIF(Dados!$B$6:$B$155,'DFs (2)'!$B46,Dados!$F$6:$F$155)+SUMIF(Dados!$B$6:$B$155,'DFs (2)'!$B46,Dados!$K$6:$K$155)+SUMIF(Dados!$G$6:$G$155,'DFs (2)'!$B46,Dados!$H$6:$H$155)+SUMIF(Dados!$B$6:$B$155,'DFs (2)'!$B46-7,Dados!$I$6:$I$155)+SUMIF(Dados!$B$6:$B$155,'DFs (2)'!$B46-7,Dados!$J$6:$J$155)) -> -1666.5 | F46: =SUM(C46:E46) -> 10845.5
...
